Workbook

Sheet financial behaviour - Form Resp
A1: Timestamp | B1: 1. Age | C1: 2. Gender | D1: 3. Monthly Allowance or Income | E1: 4. Living Type | F1: 5. How often do you shop online? | G1: 6. Average monthly spending on shopping (₹) | H1: 7. Average monthly spending on food/eating out (₹) | I1: 8. Average monthly spending on Traveling (₹) | J1: 9.Miscellaneous expenses | K1: 10. Category spent on most | L1: 11. Do social media ads influence your purchases? | M1: 12. Do you maintain a monthly budget? | N1: 13. Approximate percentage of your income you save monthly (%) | O1: 14. How satisfied are you with your savings? | P1: 15. Do you use any finance-tracking apps (e.g., Walnut, Money Manager)? | Q1: 16. How often do you track your expenses? | R1: Email Address
A2: 45970.449 | B2: 22 | C2: Prefer not to say | D2: 2500 | E2: With Family | F2: Daily | G2: 100 | H2: 300 | I2: 200 | J2: 306 | K2: =IF('financial behaviour - Form Resp'!$G2=MAX('financial behaviour - Form Resp'!$G2,'financial behaviour - Form Resp'!$H2,'financial behaviour - Form Resp'!$I2,'financial behaviour - Form Resp'!$J2),"Shopping", IF('financial behaviour - Form Resp'!$H2=MAX('financial behaviour - Form Resp'!$G2,'financial behaviour - Form Resp'!$H2,'financial behaviour - Form Resp'!$I2,'financial behaviour - Form Resp'!$J2),"Food", IF('financial behaviour - Form Resp'!$I2=MAX('financial behaviour - Form Resp'!$G2,'financial behaviour - Form Resp'!$H2,'financial behaviour - Form Resp'!$I2,'financial behaviour - Form Resp'!$J2),"Travel", IF('financial behaviour - Form Resp'!$J2=MAX('financial behaviour - Form Resp'!$G2,'financial behaviour - Form Resp'!$H2,'financial behaviour - Form Resp'!$I2,'financial behaviour - Form Resp'!$J2),"others","")))) -> others | L2: 5 | M2: Sometimes | N2: 30 | O2: 1 | P2: No | Q2: Never | R2: manasbhardwazin@gmail.com
A3: 45970.452 | B3: 21 | C3: Male | D3: 3000 | E3: Hostel | F3: Monthly | G3: 300 | H3: 2000 | I3: 200 | J3: 403 | K3: =IF('financial behaviour - Form Resp'!$G3=MAX('financial behaviour - Form Resp'!$G3,'financial behaviour - Form Resp'!$H3,'financial behaviour - Form Resp'!$I3,'financial behaviour - Form Resp'!$J3),"Shopping", IF('financial behaviour - Form Resp'!$H3=MAX('financial behaviour - Form Resp'!$G3,'financial behaviour - Form Resp'!$H3,'financial behaviour - Form Resp'!$I3,'financial behaviour - Form Resp'!$J3),"Food", IF('financial behaviour - Form Resp'!$I3=MAX('financial behaviour - Form Resp'!$G3,'financial behaviour - Form Resp'!$H3,'financial behaviour - Form Resp'!$I3,'financial behaviour - Form Resp'!$J3),"Travel", IF('financial behaviour - Form Resp'!$J3=MAX('financial behaviour - Form Resp'!$G3,'financial behaviour - Form Resp'!$H3,'financial behaviour - Form Resp'!$I3,'financial behaviour - Form Resp'!$J3),"others","")))) -> Food | L3: 3 | M3: Yes | N3: 40 | O3: 3 | P3: Yes | Q3: Monthly | R3: amritayush0722@gmail.com
A4: 45970.456 | B4: 19 | C4: Female | D4: 1000 | E4: With Family | F4: Monthly | G4: 500 | H4: 300 | I4: 400 | J4: 55 | K4: =IF('financial behaviour - Form Resp'!$G4=MAX('financial behaviour - Form Resp'!$G4,'financial behaviour - Form Resp'!$H4,'financial behaviour - Form Resp'!$I4,'financial behaviour - Form Resp'!$J4),"Shopping", IF('financial behaviour - Form Resp'!$H4=MAX('financial behaviour - Form Resp'!$G4,'financial behaviour - Form Resp'!$H4,'financial behaviour - Form Resp'!$I4,'financial behaviour - Form Resp'!$J4),"Food", IF('financial behaviour - Form Resp'!$I4=MAX('financial behaviour - Form Resp'!$G4,'financial behaviour - Form Resp'!$H4,'financial behaviour - Form Resp'!$I4,'financial behaviour - Form Resp'!$J4),"Travel", IF('financial behaviour - Form Resp'!$J4=MAX('financial behaviour - Form Resp'!$G4,'financial behaviour - Form Resp'!$H4,'financial behaviour - Form Resp'!$I4,'financial behaviour - Form Resp'!$J4),"others","")))) -> Shopping | L4: 1 | M4: No | N4: 0 | O4: 3 | P4: No | Q4: Never | R4: gunjanthakur2101@gmail.com
A5: 45970.456 | B5: 20 | C5: Male | D5: 3000 | E5: Hostel | F5: Monthly | G5: 1000 | H5: 500 | I5: 500 | J5: 444 | K5: =IF('financial behaviour - Form Resp'!$G5=MAX('financial behaviour - Form Resp'!$G5,'financial behaviour - Form Resp'!$H5,'financial behaviour - Form Resp'!$I5,'financial behaviour - Form Resp'!$J5),"Shopping", IF('financial behaviour - Form Resp'!$H5=MAX('financial behaviour - Form Resp'!$G5,'financial behaviour - Form Resp'!$H5,'financial behaviour - Form Resp'!$I5,'financial behaviour - Form Resp'!$J5),"Food", IF('financial behaviour - Form Resp'!$I5=MAX('financial behaviour - Form Resp'!$G5,'financial behaviour - Form Resp'!$H5,'financial behaviour - Form Resp'!$I5,'financial behaviour - Form Resp'!$J5),"Travel", IF('financial behaviour - Form Resp'!$J5=MAX('financial behaviour - Form Resp'!$G5,'financial behaviour - Form Resp'!$H5,'financial behaviour - Form Resp'!$I5,'financial behaviour - Form Resp'!$J5),"others","")))) -> Shopping | L5: 4 | M5: Sometimes | N5: 10 | O5: 1 | P5: No | Q5: Monthly | R5: kumar.akash02897@gmail.com
A6: 45970.457 | B6: 22 | C6: Male | D6: 3000 | E6: Hostel | F6: Monthly | G6: 600 | H6: 600 | I6: 500 | J6: 414 | K6: =IF('financial behaviour - Form Resp'!$G6=MAX('financial behaviour - Form Resp'!$G6,'financial behaviour - Form Resp'!$H6,'financial behaviour - Form Resp'!$I6,'financial behaviour - Form Resp'!$J6),"Shopping", IF('financial behaviour - Form Resp'!$H6=MAX('financial behaviour - Form Resp'!$G6,'financial behaviour - Form Resp'!$H6,'financial behaviour - Form Resp'!$I6,'financial behaviour - Form Resp'!$J6),"Food", IF('financial behaviour - Form Resp'!$I6=MAX('financial behaviour - Form Resp'!$G6,'financial behaviour - Form Resp'!$H6,'financial behaviour - Form Resp'!$I6,'financial behaviour - Form Resp'!$J6),"Travel", IF('financial behaviour - Form Resp'!$J6=MAX('financial behaviour - Form Resp'!$G6,'financial behaviour - Form Resp'!$H6,'financial behaviour - Form Resp'!$I6,'financial behaviour - Form Resp'!$J6),"others","")))) -> Shopping | L6: 1 | M6: Sometimes | N6: 10 | O6: 1 | P6: No | Q6: Never | R6: koundalaniket410@gmail.com
A7: 45970.461 | B7: 20 | C7: Female | D7: 10000 | E7: Hostel | F7: Monthly | G7: 300 | H7: 1000 | I7: 500 | J7: 639 | K7: =IF('financial behaviour - Form Resp'!$G7=MAX('financial behaviour - Form Resp'!$G7,'financial behaviour - Form Resp'!$H7,'financial behaviour - Form Resp'!$I7,'financial behaviour - Form Resp'!$J7),"Shopping", IF('financial behaviour - Form Resp'!$H7=MAX('financial behaviour - Form Resp'!$G7,'financial behaviour - Form Resp'!$H7,'financial behaviour - Form Resp'!$I7,'financial behaviour - Form Resp'!$J7),"Food", IF('financial behaviour - Form Resp'!$I7=MAX('financial behaviour - Form Resp'!$G7,'financial behaviour - Form Resp'!$H7,'financial behaviour - Form Resp'!$I7,'financial behaviour - Form Resp'!$J7),"Travel", IF('financial behaviour - Form Resp'!$J7=MAX('financial behaviour - Form Resp'!$G7,'financial behaviour - Form Resp'!$H7,'financial behaviour - Form Resp'!$I7,'financial behaviour - Form Resp'!$J7),"others","")))) -> Food | L7: 1 | M7: Yes | N7: 0 | O7: 2 | P7: No | Q7: Never | R7: sanjay14aishwarya1823@gmail.com
A8: 45970.463 | B8: 22 | C8: Male | D8: 20000 | E8: PG | F8: Monthly | G8: 2500 | H8: 10000 | I8: 2500 | J8: 1884 | K8: =IF('financial behaviour - Form Resp'!$G8=MAX('financial behaviour - Form Resp'!$G8,'financial behaviour - Form Resp'!$H8,'financial behaviour - Form Resp'!$I8,'financial behaviour - Form Resp'!$J8),"Shopping", IF('financial behaviour - Form Resp'!$H8=MAX('financial behaviour - Form Resp'!$G8,'financial behaviour - Form Resp'!$H8,'financial behaviour - Form Resp'!$I8,'financial behaviour - Form Resp'!$J8),"Food", IF('financial behaviour - Form Resp'!$I8=MAX('financial behaviour - Form Resp'!$G8,'financial behaviour - Form Resp'!$H8,'financial behaviour - Form Resp'!$I8,'financial behaviour - Form Resp'!$J8),"Travel", IF('financial behaviour - Form Resp'!$J8=MAX('financial behaviour - Form Resp'!$G8,'financial behaviour - Form Resp'!$H8,'financial behaviour - Form Resp'!$I8,'financial behaviour - Form Resp'!$J8),"others","")))) -> Food | L8: 4 | M8: No | N8: 0 | O8: 1 | P8: No | Q8: Weekly | R8: adityaranjanbehera23@gmail.com
A9: 45970.463 | B9: 21 | C9: Male | D9: 10000 | E9: PG | F9: Monthly | G9: 3000 | H9: 3000 | I9: 1000 | J9: 1321 | K9: =IF('financial behaviour - Form Resp'!$G9=MAX('financial behaviour - Form Resp'!$G9,'financial behaviour - Form Resp'!$H9,'financial behaviour - Form Resp'!$I9,'financial behaviour - Form Resp'!$J9),"Shopping", IF('financial behaviour - Form Resp'!$H9=MAX('financial behaviour - Form Resp'!$G9,'financial behaviour - Form Resp'!$H9,'financial behaviour - Form Resp'!$I9,'financial behaviour - Form Resp'!$J9),"Food", IF('financial behaviour - Form Resp'!$I9=MAX('financial behaviour - Form Resp'!$G9,'financial behaviour - Form Resp'!$H9,'financial behaviour - Form Resp'!$I9,'financial behaviour - Form Resp'!$J9),"Travel", IF('financial behaviour - Form Resp'!$J9=MAX('financial behaviour - Form Resp'!$G9,'financial behaviour - Form Resp'!$H9,'financial behaviour - Form Resp'!$I9,'financial behaviour - Form Resp'!$J9),"others","")))) -> Shopping | L9: 2 | M9: Sometimes | N9: 5 | O9: 5 | P9: No | Q9: Weekly | R9: paruchuriharsha123@gmail.com
A10: 45970.465 | B10: 19 | C10: Male | D10: 3000 | E10: Hostel | F10: Monthly | G10: 500 | H10: 2000 | I10: 400 | J10: 406 | K10: =IF('financial behaviour - Form Resp'!$G10=MAX('financial behaviour - Form Resp'!$G10,'financial behaviour - Form Resp'!$H10,'financial behaviour - Form Resp'!$I10,'financial behaviour - Form Resp'!$J10),"Shopping", IF('financial behaviour - Form Resp'!$H10=MAX('financial behaviour - Form Resp'!$G10,'financial behaviour - Form Resp'!$H10,'financial behaviour - Form Resp'!$I10,'financial behaviour - Form Resp'!$J10),"Food", IF('financial behaviour - Form Resp'!$I10=MAX('financial behaviour - Form Resp'!$G10,'financial behaviour - Form Resp'!$H10,'financial behaviour - Form Resp'!$I10,'financial behaviour - Form Resp'!$J10),"Travel", IF('financial behaviour - Form Resp'!$J10=MAX('financial behaviour - Form Resp'!$G10,'financial behaviour - Form Resp'!$H10,'financial behaviour - Form Resp'!$I10,'financial behaviour - Form Resp'!$J10),"others","")))) -> Food | L10: 2 | M10: Sometimes | N10: 10 | O10: 2 | P10: No | Q10: Monthly | R10: mohankowshik18@gmail.com
A11: 45970.467 | B11: 23 | C11: Male | D11: 1500 | E11: With Family | F11: Never | G11: 0 | H11: 300 | I11: 800 | J11: 170 | K11: =IF('financial behaviour - Form Resp'!$G11=MAX('financial behaviour - Form Resp'!$G11,'financial behaviour - Form Resp'!$H11,'financial behaviour - Form Resp'!$I11,'financial behaviour - Form Resp'!$J11),"Shopping", IF('financial behaviour - Form Resp'!$H11=MAX('financial behaviour - Form Resp'!$G11,'financial behaviour - Form Resp'!$H11,'financial behaviour - Form Resp'!$I11,'financial behaviour - Form Resp'!$J11),"Food", IF('financial behaviour - Form Resp'!$I11=MAX('financial behaviour - Form Resp'!$G11,'financial behaviour - Form Resp'!$H11,'financial behaviour - Form Resp'!$I11,'financial behaviour - Form Resp'!$J11),"Travel", IF('financial behaviour - Form Resp'!$J11=MAX('financial behaviour - Form Resp'!$G11,'financial behaviour - Form Resp'!$H11,'financial behaviour - Form Resp'!$I11,'financial behaviour - Form Resp'!$J11),"others","")))) -> Travel | L11: 1 | M11: Yes | N11: 5 | O11: 1 | P11: No | Q11: Never | R11: bhupi102yahoo@gmail.com
A12: 45970.469 | B12: 22 | C12: Female | D12: 100 | E12: Hostel | F12: Monthly | G12: 300 | H12: 200 | I12: 100 | J12: 11 | K12: =IF('financial behaviour - Form Resp'!$G12=MAX('financial behaviour - Form Resp'!$G12,'financial behaviour - Form Resp'!$H12,'financial behaviour - Form Resp'!$I12,'financial behaviour - Form Resp'!$J12),"Shopping", IF('financial behaviour - Form Resp'!$H12=MAX('financial behaviour - Form Resp'!$G12,'financial behaviour - Form Resp'!$H12,'financial behaviour - Form Resp'!$I12,'financial behaviour - Form Resp'!$J12),"Food", IF('financial behaviour - Form Resp'!$I12=MAX('financial behaviour - Form Resp'!$G12,'financial behaviour - Form Resp'!$H12,'financial behaviour - Form Resp'!$I12,'financial behaviour - Form Resp'!$J12),"Travel", IF('financial behaviour - Form Resp'!$J12=MAX('financial behaviour - Form Resp'!$G12,'financial behaviour - Form Resp'!$H12,'financial behaviour - Form Resp'!$I12,'financial behaviour - Form Resp'!$J12),"others","")))) -> Shopping | L12: 1 | M12: No | N12: 0 | O12: 1 | P12: No | Q12: Monthly | R12: anusaha9080@gmail.com
A13: 45970.469 | B13: 25 | C13: Female | D13: 6000 | E13: Hostel | F13: Monthly | G13: 1000 | H13: 3000 | I13: 5000 | J13: 774 | K13: =IF('financial behaviour - Form Resp'!$G13=MAX('financial behaviour - Form Resp'!$G13,'financial behaviour - Form Resp'!$H13,'financial behaviour - Form Resp'!$I13,'financial behaviour - Form Resp'!$J13),"Shopping", IF('financial behaviour - Form Resp'!$H13=MAX('financial behaviour - Form Resp'!$G13,'financial behaviour - Form Resp'!$H13,'financial behaviour - Form Resp'!$I13,'financial behaviour - Form Resp'!$J13),"Food", IF('financial behaviour - Form Resp'!$I13=MAX('financial behaviour - Form Resp'!$G13,'financial behaviour - Form Resp'!$H13,'financial behaviour - Form Resp'!$I13,'financial behaviour - Form Resp'!$J13),"Travel", IF('financial behaviour - Form Resp'!$J13=MAX('financial behaviour - Form Resp'!$G13,'financial behaviour - Form Resp'!$H13,'financial behaviour - Form Resp'!$I13,'financial behaviour - Form Resp'!$J13),"others","")))) -> Travel | L13: 4 | M13: Sometimes | N13: 20 | O13: 2 | P13: No | Q13: Monthly | R13: anjaliankita1128@gmail.com
... A135: 45992.543 | B135: 20 | C135: Female | D135: 4000 | E135: Hostel | F135: Never | G135: 100 | H135: 3000 | I135: 1000 | J135: 416 | K135: =IF('financial behaviour - Form Resp'!$G135=MAX('financial behaviour - Form Resp'!$G135,'financial behaviour - Form Resp'!$H135,'financial behaviour - Form Resp'!$I135,'financial behaviour - Form Resp'!$J135),"Shopping", IF('financial behaviour - Form Resp'!$H135=MAX('financial behaviour - Form Resp'!$G135,'financial behaviour - Form Resp'!$H135,'financial behaviour - Form Resp'!$I135,'financial behaviour - Form Resp'!$J135),"Food", IF('financial behaviour - Form Resp'!$I135=MAX('financial behaviour - Form Resp'!$G135,'financial behaviour - Form Resp'!$H135,'financial behaviour - Form Resp'!$I135,'financial behaviour - Form Resp'!$J135),"Travel", IF('financial behaviour - Form Resp'!$J135=MAX('financial behaviour - Form Resp'!$G135,'financial behaviour - Form Resp'!$H135,'financial behaviour - Form Resp'!$I135,'financial behaviour - Form Resp'!$J135),"others","")))) -> Food | L135: 1 | M135: No | N135: 2 | O135: 4 | P135: No | Q135: Never | R135: kap89797@gmail.com
A136: 45999.395 | B136: 24 | C136: Female | D136: 5000 | E136: Hostel | F136: Weekly | G136: 2500 | H136: 2000 | I136: 500 | J136: 627 | K136: =IF('financial behaviour - Form Resp'!$G136=MAX('financial behaviour - Form Resp'!$G136,'financial behaviour - Form Resp'!$H136,'financial behaviour - Form Resp'!$I136,'financial behaviour - Form Resp'!$J136),"Shopping", IF('financial behaviour - Form Resp'!$H136=MAX('financial behaviour - Form Resp'!$G136,'financial behaviour - Form Resp'!$H136,'financial behaviour - Form Resp'!$I136,'financial behaviour - Form Resp'!$J136),"Food", IF('financial behaviour - Form Resp'!$I136=MAX('financial behaviour - Form Resp'!$G136,'financial behaviour - Form Resp'!$H136,'financial behaviour - Form Resp'!$I136,'financial behaviour - Form Resp'!$J136),"Travel", IF('financial behaviour - Form Resp'!$J136=MAX('financial behaviour - Form Resp'!$G136,'financial behaviour - Form Resp'!$H136,'financial behaviour - Form Resp'!$I136,'financial behaviour - Form Resp'!$J136),"others","")))) -> Shopping | L136: 4 | M136: No | N136: 10 | O136: 3 | P136: No | Q136: Monthly
A137: 45999.471 | B137: 23 | C137: Male | D137: 4000 | E137: Hostel | F137: Monthly | G137: 500 | H137: 1500 | I137: 500 | J137: 459 | K137: =IF('financial behaviour - Form Resp'!$G137=MAX('financial behaviour - Form Resp'!$G137,'financial behaviour - Form Resp'!$H137,'financial behaviour - Form Resp'!$I137,'financial behaviour - Form Resp'!$J137),"Shopping", IF('financial behaviour - Form Resp'!$H137=MAX('financial behaviour - Form Resp'!$G137,'financial behaviour - Form Resp'!$H137,'financial behaviour - Form Resp'!$I137,'financial behaviour - Form Resp'!$J137),"Food", IF('financial behaviour - Form Resp'!$I137=MAX('financial behaviour - Form Resp'!$G137,'financial behaviour - Form Resp'!$H137,'financial behaviour - Form Resp'!$I137,'financial behaviour - Form Resp'!$J137),"Travel", IF('financial behaviour - Form Resp'!$J137=MAX('financial behaviour - Form Resp'!$G137,'financial behaviour - Form Resp'!$H137,'financial behaviour - Form Resp'!$I137,'financial behaviour - Form Resp'!$J137),"others","")))) -> Food | L137: 2 | M137: Sometimes | N137: 45 | O137: 3 | P137: Yes | Q137: Monthly
A138: 45999.472 | B138: 20 | C138: Male | D138: 3000 | E138: With Family | F138: Monthly | G138: 700 | H138: 1500 | I138: 200 | J138: 421 | K138: =IF('financial behaviour - Form Resp'!$G138=MAX('financial behaviour - Form Resp'!$G138,'financial behaviour - Form Resp'!$H138,'financial behaviour - Form Resp'!$I138,'financial behaviour - Form Resp'!$J138),"Shopping", IF('financial behaviour - Form Resp'!$H138=MAX('financial behaviour - Form Resp'!$G138,'financial behaviour - Form Resp'!$H138,'financial behaviour - Form Resp'!$I138,'financial behaviour - Form Resp'!$J138),"Food", IF('financial behaviour - Form Resp'!$I138=MAX('financial behaviour - Form Resp'!$G138,'financial behaviour - Form Resp'!$H138,'financial behaviour - Form Resp'!$I138,'financial behaviour - Form Resp'!$J138),"Travel", IF('financial behaviour - Form Resp'!$J138=MAX('financial behaviour - Form Resp'!$G138,'financial behaviour - Form Resp'!$H138,'financial behaviour - Form Resp'!$I138,'financial behaviour - Form Resp'!$J138),"others","")))) -> Food | L138: 4 | M138: No | N138: 30 | O138: 4 | P138: Yes | Q138: Monthly
A139: 45999.763 | B139: 21 | C139: Female | D139: 4000 | E139: PG | F139: Weekly | G139: 1000 | H139: 2000 | I139: 0 | J139: 373 | K139: =IF('financial behaviour - Form Resp'!$G139=MAX('financial behaviour - Form Resp'!$G139,'financial behaviour - Form Resp'!$H139,'financial behaviour - Form Resp'!$I139,'financial behaviour - Form Resp'!$J139),"Shopping", IF('financial behaviour - Form Resp'!$H139=MAX('financial behaviour - Form Resp'!$G139,'financial behaviour - Form Resp'!$H139,'financial behaviour - Form Resp'!$I139,'financial behaviour - Form Resp'!$J139),"Food", IF('financial behaviour - Form Resp'!$I139=MAX('financial behaviour - Form Resp'!$G139,'financial behaviour - Form Resp'!$H139,'financial behaviour - Form Resp'!$I139,'financial behaviour - Form Resp'!$J139),"Travel", IF('financial behaviour - Form Resp'!$J139=MAX('financial behaviour - Form Resp'!$G139,'financial behaviour - Form Resp'!$H139,'financial behaviour - Form Resp'!$I139,'financial behaviour - Form Resp'!$J139),"others","")))) -> Food | L139: 4 | M139: Yes | N139: 25 | O139: 4 | P139: No | Q139: Weekly
A140: 45999.764 | B140: 22 | C140: Male | D140: 5000 | E140: Hostel | F140: Monthly | G140: 1000 | H140: 1500 | I140: 400 | J140: 521 | K140: =IF('financial behaviour - Form Resp'!$G140=MAX('financial behaviour - Form Resp'!$G140,'financial behaviour - Form Resp'!$H140,'financial behaviour - Form Resp'!$I140,'financial behaviour - Form Resp'!$J140),"Shopping", IF('financial behaviour - Form Resp'!$H140=MAX('financial behaviour - Form Resp'!$G140,'financial behaviour - Form Resp'!$H140,'financial behaviour - Form Resp'!$I140,'financial behaviour - Form Resp'!$J140),"Food", IF('financial behaviour - Form Resp'!$I140=MAX('financial behaviour - Form Resp'!$G140,'financial behaviour - Form Resp'!$H140,'financial behaviour - Form Resp'!$I140,'financial behaviour - Form Resp'!$J140),"Travel", IF('financial behaviour - Form Resp'!$J140=MAX('financial behaviour - Form Resp'!$G140,'financial behaviour - Form Resp'!$H140,'financial behaviour - Form Resp'!$I140,'financial behaviour - Form Resp'!$J140),"others","")))) -> Food | L140: 2 | M140: Yes | N140: 30 | O140: 4 | P140: Yes | Q140: Never
A141: 45999.766 | B141: 20 | C141: Male | D141: 4500 | E141: PG | F141: Weekly | G141: 2000 | H141: 1000 | I141: 1500 | J141: 328 | K141: =IF('financial behaviour - Form Resp'!$G141=MAX('financial behaviour - Form Resp'!$G141,'financial behaviour - Form Resp'!$H141,'financial behaviour - Form Resp'!$I141,'financial behaviour - Form Resp'!$J141),"Shopping", IF('financial behaviour - Form Resp'!$H141=MAX('financial behaviour - Form Resp'!$G141,'financial behaviour - Form Resp'!$H141,'financial behaviour - Form Resp'!$I141,'financial behaviour - Form Resp'!$J141),"Food", IF('financial behaviour - Form Resp'!$I141=MAX('financial behaviour - Form Resp'!$G141,'financial behaviour - Form Resp'!$H141,'financial behaviour - Form Resp'!$I141,'financial behaviour - Form Resp'!$J141),"Travel", IF('financial behaviour - Form Resp'!$J141=MAX('financial behaviour - Form Resp'!$G141,'financial behaviour - Form Resp'!$H141,'financial behaviour - Form Resp'!$I141,'financial behaviour - Form Resp'!$J141),"others","")))) -> Shopping | L141: 3 | M141: Sometimes | N141: 1 | O141: 1 | P141: Yes | Q141: Monthly
A142: 45999.77 | B142: 22 | C142: Male | D142: 2000 | E142: With Family | F142: Monthly | G142: 0 | H142: 1000 | I142: 1000 | J142: 285 | K142: =IF('financial behaviour - Form Resp'!$G142=MAX('financial behaviour - Form Resp'!$G142,'financial behaviour - Form Resp'!$H142,'financial behaviour - Form Resp'!$I142,'financial behaviour - Form Resp'!$J142),"Shopping", IF('financial behaviour - Form Resp'!$H142=MAX('financial behaviour - Form Resp'!$G142,'financial behaviour - Form Resp'!$H142,'financial behaviour - Form Resp'!$I142,'financial behaviour - Form Resp'!$J142),"Food", IF('financial behaviour - Form Resp'!$I142=MAX('financial behaviour - Form Resp'!$G142,'financial behaviour - Form Resp'!$H142,'financial behaviour - Form Resp'!$I142,'financial behaviour - Form Resp'!$J142),"Travel", IF('financial behaviour - Form Resp'!$J142=MAX('financial behaviour - Form Resp'!$G142,'financial behaviour - Form Resp'!$H142,'financial behaviour - Form Resp'!$I142,'financial behaviour - Form Resp'!$J142),"others","")))) -> Food | L142: 1 | M142: Sometimes | N142: 1 | O142: 4 | P142: No | Q142: Monthly
A143: 45999.771 | B143: 19 | C143: Female | D143: 6000 | E143: Hostel | F143: Monthly | G143: 2000 | H143: 3000 | I143: 500 | J143: 818 | K143: =IF('financial behaviour - Form Resp'!$G143=MAX('financial behaviour - Form Resp'!$G143,'financial behaviour - Form Resp'!$H143,'financial behaviour - Form Resp'!$I143,'financial behaviour - Form Resp'!$J143),"Shopping", IF('financial behaviour - Form Resp'!$H143=MAX('financial behaviour - Form Resp'!$G143,'financial behaviour - Form Resp'!$H143,'financial behaviour - Form Resp'!$I143,'financial behaviour - Form Resp'!$J143),"Food", IF('financial behaviour - Form Resp'!$I143=MAX('financial behaviour - Form Resp'!$G143,'financial behaviour - Form Resp'!$H143,'financial behaviour - Form Resp'!$I143,'financial behaviour - Form Resp'!$J143),"Travel", IF('financial behaviour - Form Resp'!$J143=MAX('financial behaviour - Form Resp'!$G143,'financial behaviour - Form Resp'!$H143,'financial behaviour - Form Resp'!$I143,'financial behaviour - Form Resp'!$J143),"others","")))) -> Food | L143: 4 | M143: Yes | N143: 30 | O143: 3 | P143: No | Q143: Weekly
A144: 45999.772 | B144: 20 | C144: Prefer not to say | D144: 10000 | E144: PG | F144: Weekly | G144: 2000 | H144: 4000 | I144: 2000 | J144: 1360 | K144: =IF('financial behaviour - Form Resp'!$G144=MAX('financial behaviour - Form Resp'!$G144,'financial behaviour - Form Resp'!$H144,'financial behaviour - Form Resp'!$I144,'financial behaviour - Form Resp'!$J144),"Shopping", IF('financial behaviour - Form Resp'!$H144=MAX('financial behaviour - Form Resp'!$G144,'financial behaviour - Form Resp'!$H144,'financial behaviour - Form Resp'!$I144,'financial behaviour - Form Resp'!$J144),"Food", IF('financial behaviour - Form Resp'!$I144=MAX('financial behaviour - Form Resp'!$G144,'financial behaviour - Form Resp'!$H144,'financial behaviour - Form Resp'!$I144,'financial behaviour - Form Resp'!$J144),"Travel", IF('financial behaviour - Form Resp'!$J144=MAX('financial behaviour - Form Resp'!$G144,'financial behaviour - Form Resp'!$H144,'financial behaviour - Form Resp'!$I144,'financial behaviour - Form Resp'!$J144),"others","")))) -> Food | L144: 3 | M144: No | N144: 20 | O144: 4 | P144: Yes | Q144: Never
A145: 45999.774 | B145: 23 | C145: Female | D145: 7500 | E145: PG | F145: Weekly | G145: 3000 | H145: 2000 | I145: 5000 | J145: 547 | K145: =IF('financial behaviour - Form Resp'!$G145=MAX('financial behaviour - Form Resp'!$G145,'financial behaviour - Form Resp'!$H145,'financial behaviour - Form Resp'!$I145,'financial behaviour - Form Resp'!$J145),"Shopping", IF('financial behaviour - Form Resp'!$H145=MAX('financial behaviour - Form Resp'!$G145,'financial behaviour - Form Resp'!$H145,'financial behaviour - Form Resp'!$I145,'financial behaviour - Form Resp'!$J145),"Food", IF('financial behaviour - Form Resp'!$I145=MAX('financial behaviour - Form Resp'!$G145,'financial behaviour - Form Resp'!$H145,'financial behaviour - Form Resp'!$I145,'financial behaviour - Form Resp'!$J145),"Travel", IF('financial behaviour - Form Resp'!$J145=MAX('financial behaviour - Form Resp'!$G145,'financial behaviour - Form Resp'!$H145,'financial behaviour - Form Resp'!$I145,'financial behaviour - Form Resp'!$J145),"others","")))) -> Travel | L145: 4 | M145: Yes | N145: 1 | O145: 3 | P145: Yes | Q145: Never
A146: 45999.776 | B146: 20 | C146: Female | D146: 1 | E146: PG | F146: Weekly | G146: 3000 | H146: 4000 | I146: 2100 | J146: 0 | K146: =IF('financial behaviour - Form Resp'!$G146=MAX('financial behaviour - Form Resp'!$G146,'financial behaviour - Form Resp'!$H146,'financial behaviour - Form Resp'!$I146,'financial behaviour - Form Resp'!$J146),"Shopping", IF('financial behaviour - Form Resp'!$H146=MAX('financial behaviour - Form Resp'!$G146,'financial behaviour - Form Resp'!$H146,'financial behaviour - Form Resp'!$I146,'financial behaviour - Form Resp'!$J146),"Food", IF('financial behaviour - Form Resp'!$I146=MAX('financial behaviour - Form Resp'!$G146,'financial behaviour - Form Resp'!$H146,'financial behaviour - Form Resp'!$I146,'financial behaviour - Form Resp'!$J146),"Travel", IF('financial behaviour - Form Resp'!$J146=MAX('financial behaviour - Form Resp'!$G146,'financial behaviour - Form Resp'!$H146,'financial behaviour - Form Resp'!$I146,'financial behaviour - Form Resp'!$J146),"others","")))) -> Food | L146: 4 | M146: Yes | N146: 27 | O146: 2 | P146: No | Q146: Daily
A147: 45999.776 | B147: 19 | C147: Female | D147: 11000 | E147: Hostel | F147: Daily | G147: 3000 | H147: 2000 | I147: 4000 | J147: 1560 | K147: =IF('financial behaviour - Form Resp'!$G147=MAX('financial behaviour - Form Resp'!$G147,'financial behaviour - Form Resp'!$H147,'financial behaviour - Form Resp'!$I147,'financial behaviour - Form Resp'!$J147),"Shopping", IF('financial behaviour - Form Resp'!$H147=MAX('financial behaviour - Form Resp'!$G147,'financial behaviour - Form Resp'!$H147,'financial behaviour - Form Resp'!$I147,'financial behaviour - Form Resp'!$J147),"Food", IF('financial behaviour - Form Resp'!$I147=MAX('financial behaviour - Form Resp'!$G147,'financial behaviour - Form Resp'!$H147,'financial behaviour - Form Resp'!$I147,'financial behaviour - Form Resp'!$J147),"Travel", IF('financial behaviour - Form Resp'!$J147=MAX('financial behaviour - Form Resp'!$G147,'financial behaviour - Form Resp'!$H147,'financial behaviour - Form Resp'!$I147,'financial behaviour - Form Resp'!$J147),"others","")))) -> Travel | L147: 4 | M147: Yes | N147: 25 | O147: 2 | P147: No | Q147: Weekly
... A206: 46004.814 | B206: 15 | C206: Female | D206: 23890.92 | E206: With Family | F206: Weekly | G206: 7.56 | H206: 3191.962 | I206: 4090 | J206: 2479 | K206: =IF('financial behaviour - Form Resp'!$G206=MAX('financial behaviour - Form Resp'!$G206,'financial behaviour - Form Resp'!$H206,'financial behaviour - Form Resp'!$I206,'financial behaviour - Form Resp'!$J206),"Shopping", IF('financial behaviour - Form Resp'!$H206=MAX('financial behaviour - Form Resp'!$G206,'financial behaviour - Form Resp'!$H206,'financial behaviour - Form Resp'!$I206,'financial behaviour - Form Resp'!$J206),"Food", IF('financial behaviour - Form Resp'!$I206=MAX('financial behaviour - Form Resp'!$G206,'financial behaviour - Form Resp'!$H206,'financial behaviour - Form Resp'!$I206,'financial behaviour - Form Resp'!$J206),"Travel", IF('financial behaviour - Form Resp'!$J206=MAX('financial behaviour - Form Resp'!$G206,'financial behaviour - Form Resp'!$H206,'financial behaviour - Form Resp'!$I206,'financial behaviour - Form Resp'!$J206),"others","")))) -> Travel | L206: 2 | M206: Yes | N206: 22 | O206: 2 | P206: Yes | Q206: Weekly
B207: 20 | C207: Prefer not to say | D207: 15749.74 | E207: PG | F207: Monthly | G207: 64.86 | H207: 3780 | I207: 0 | J207: 848 | K207: =IF('financial behaviour - Form Resp'!$G207=MAX('financial behaviour - Form Resp'!$G207,'financial behaviour - Form Resp'!$H207,'financial behaviour - Form Resp'!$I207,'financial behaviour - Form Resp'!$J207),"Shopping", IF('financial behaviour - Form Resp'!$H207=MAX('financial behaviour - Form Resp'!$G207,'financial behaviour - Form Resp'!$H207,'financial behaviour - Form Resp'!$I207,'financial behaviour - Form Resp'!$J207),"Food", IF('financial behaviour - Form Resp'!$I207=MAX('financial behaviour - Form Resp'!$G207,'financial behaviour - Form Resp'!$H207,'financial behaviour - Form Resp'!$I207,'financial behaviour - Form Resp'!$J207),"Travel", IF('financial behaviour - Form Resp'!$J207=MAX('financial behaviour - Form Resp'!$G207,'financial behaviour - Form Resp'!$H207,'financial behaviour - Form Resp'!$I207,'financial behaviour - Form Resp'!$J207),"others","")))) -> Food | L207: 2 | M207: Sometimes | N207: 43 | O207: 5 | P207: No | Q207: Weekly
B208: 19 | C208: Prefer not to say | D208: 28035.02 | E208: Hostel | F208: Never | G208: 1604.38 | H208: 3807.962 | I208: 177.86 | J208: 1406 | K208: =IF('financial behaviour - Form Resp'!$G208=MAX('financial behaviour - Form Resp'!$G208,'financial behaviour - Form Resp'!$H208,'financial behaviour - Form Resp'!$I208,'financial behaviour - Form Resp'!$J208),"Shopping", IF('financial behaviour - Form Resp'!$H208=MAX('financial behaviour - Form Resp'!$G208,'financial behaviour - Form Resp'!$H208,'financial behaviour - Form Resp'!$I208,'financial behaviour - Form Resp'!$J208),"Food", IF('financial behaviour - Form Resp'!$I208=MAX('financial behaviour - Form Resp'!$G208,'financial behaviour - Form Resp'!$H208,'financial behaviour - Form Resp'!$I208,'financial behaviour - Form Resp'!$J208),"Travel", IF('financial behaviour - Form Resp'!$J208=MAX('financial behaviour - Form Resp'!$G208,'financial behaviour - Form Resp'!$H208,'financial behaviour - Form Resp'!$I208,'financial behaviour - Form Resp'!$J208),"others","")))) -> Food | L208: 2 | M208: Sometimes | N208: 50 | O208: 1 | P208: Yes | Q208: Weekly
B209: 15 | C209: Prefer not to say | D209: 3361 | E209: PG | F209: Monthly | G209: 7517 | H209: 1884 | I209: 6839 | J209: 313 | K209: =IF('financial behaviour - Form Resp'!$G209=MAX('financial behaviour - Form Resp'!$G209,'financial behaviour - Form Resp'!$H209,'financial behaviour - Form Resp'!$I209,'financial behaviour - Form Resp'!$J209),"Shopping", IF('financial behaviour - Form Resp'!$H209=MAX('financial behaviour - Form Resp'!$G209,'financial behaviour - Form Resp'!$H209,'financial behaviour - Form Resp'!$I209,'financial behaviour - Form Resp'!$J209),"Food", IF('financial behaviour - Form Resp'!$I209=MAX('financial behaviour - Form Resp'!$G209,'financial behaviour - Form Resp'!$H209,'financial behaviour - Form Resp'!$I209,'financial behaviour - Form Resp'!$J209),"Travel", IF('financial behaviour - Form Resp'!$J209=MAX('financial behaviour - Form Resp'!$G209,'financial behaviour - Form Resp'!$H209,'financial behaviour - Form Resp'!$I209,'financial behaviour - Form Resp'!$J209),"others","")))) -> Shopping | L209: 1 | M209: No | N209: 52 | O209: 2 | P209: No | Q209: Monthly
B210: 21 | C210: Prefer not to say | D210: 3831.763 | E210: With Family | F210: Daily | G210: 3284.44 | H210: 2343.94 | I210: 208.5 | J210: 234 | K210: =IF('financial behaviour - Form Resp'!$G210=MAX('financial behaviour - Form Resp'!$G210,'financial behaviour - Form Resp'!$H210,'financial behaviour - Form Resp'!$I210,'financial behaviour - Form Resp'!$J210),"Shopping", IF('financial behaviour - Form Resp'!$H210=MAX('financial behaviour - Form Resp'!$G210,'financial behaviour - Form Resp'!$H210,'financial behaviour - Form Resp'!$I210,'financial behaviour - Form Resp'!$J210),"Food", IF('financial behaviour - Form Resp'!$I210=MAX('financial behaviour - Form Resp'!$G210,'financial behaviour - Form Resp'!$H210,'financial behaviour - Form Resp'!$I210,'financial behaviour - Form Resp'!$J210),"Travel", IF('financial behaviour - Form Resp'!$J210=MAX('financial behaviour - Form Resp'!$G210,'financial behaviour - Form Resp'!$H210,'financial behaviour - Form Resp'!$I210,'financial behaviour - Form Resp'!$J210),"others","")))) -> Shopping | L210: 1 | M210: No | N210: 0 | O210: 4 | P210: No | Q210: Weekly
B211: 20 | C211: Male | D211: 182.08 | E211: With Family | F211: Monthly | G211: 3978.2 | H211: 1363 | I211: 11092 | J211: 0 | K211: =IF('financial behaviour - Form Resp'!$G211=MAX('financial behaviour - Form Resp'!$G211,'financial behaviour - Form Resp'!$H211,'financial behaviour - Form Resp'!$I211,'financial behaviour - Form Resp'!$J211),"Shopping", IF('financial behaviour - Form Resp'!$H211=MAX('financial behaviour - Form Resp'!$G211,'financial behaviour - Form Resp'!$H211,'financial behaviour - Form Resp'!$I211,'financial behaviour - Form Resp'!$J211),"Food", IF('financial behaviour - Form Resp'!$I211=MAX('financial behaviour - Form Resp'!$G211,'financial behaviour - Form Resp'!$H211,'financial behaviour - Form Resp'!$I211,'financial behaviour - Form Resp'!$J211),"Travel", IF('financial behaviour - Form Resp'!$J211=MAX('financial behaviour - Form Resp'!$G211,'financial behaviour - Form Resp'!$H211,'financial behaviour - Form Resp'!$I211,'financial behaviour - Form Resp'!$J211),"others","")))) -> Travel | L211: 1 | M211: No | N211: 0 | O211: 3 | P211: Yes | Q211: Never
B212: 20 | C212: Prefer not to say | D212: 16718.02 | E212: Hostel | F212: Weekly | G212: 5351.78 | H212: 3127.06 | I212: 9111 | J212: 2004 | K212: =IF('financial behaviour - Form Resp'!$G212=MAX('financial behaviour - Form Resp'!$G212,'financial behaviour - Form Resp'!$H212,'financial behaviour - Form Resp'!$I212,'financial behaviour - Form Resp'!$J212),"Shopping", IF('financial behaviour - Form Resp'!$H212=MAX('financial behaviour - Form Resp'!$G212,'financial behaviour - Form Resp'!$H212,'financial behaviour - Form Resp'!$I212,'financial behaviour - Form Resp'!$J212),"Food", IF('financial behaviour - Form Resp'!$I212=MAX('financial behaviour - Form Resp'!$G212,'financial behaviour - Form Resp'!$H212,'financial behaviour - Form Resp'!$I212,'financial behaviour - Form Resp'!$J212),"Travel", IF('financial behaviour - Form Resp'!$J212=MAX('financial behaviour - Form Resp'!$G212,'financial behaviour - Form Resp'!$H212,'financial behaviour - Form Resp'!$I212,'financial behaviour - Form Resp'!$J212),"others","")))) -> Travel | L212: 4 | M212: Sometimes | N212: 34 | O212: 5 | P212: No | Q212: Never
B213: 15 | C213: Female | D213: 333.56 | E213: With Family | F213: Weekly | G213: 6250 | H213: 8443 | I213: 0 | J213: 0 | K213: =IF('financial behaviour - Form Resp'!$G213=MAX('financial behaviour - Form Resp'!$G213,'financial behaviour - Form Resp'!$H213,'financial behaviour - Form Resp'!$I213,'financial behaviour - Form Resp'!$J213),"Shopping", IF('financial behaviour - Form Resp'!$H213=MAX('financial behaviour - Form Resp'!$G213,'financial behaviour - Form Resp'!$H213,'financial behaviour - Form Resp'!$I213,'financial behaviour - Form Resp'!$J213),"Food", IF('financial behaviour - Form Resp'!$I213=MAX('financial behaviour - Form Resp'!$G213,'financial behaviour - Form Resp'!$H213,'financial behaviour - Form Resp'!$I213,'financial behaviour - Form Resp'!$J213),"Travel", IF('financial behaviour - Form Resp'!$J213=MAX('financial behaviour - Form Resp'!$G213,'financial behaviour - Form Resp'!$H213,'financial behaviour - Form Resp'!$I213,'financial behaviour - Form Resp'!$J213),"others","")))) -> Food | L213: 3 | M213: Sometimes | N213: 2 | O213: 1 | P213: Yes | Q213: Weekly
B214: 25 | C214: Prefer not to say | D214: 2971.52 | E214: PG | F214: Weekly | G214: 409 | H214: 227.962 | I214: 3097.6 | J214: 236 | K214: =IF('financial behaviour - Form Resp'!$G214=MAX('financial behaviour - Form Resp'!$G214,'financial behaviour - Form Resp'!$H214,'financial behaviour - Form Resp'!$I214,'financial behaviour - Form Resp'!$J214),"Shopping", IF('financial behaviour - Form Resp'!$H214=MAX('financial behaviour - Form Resp'!$G214,'financial behaviour - Form Resp'!$H214,'financial behaviour - Form Resp'!$I214,'financial behaviour - Form Resp'!$J214),"Food", IF('financial behaviour - Form Resp'!$I214=MAX('financial behaviour - Form Resp'!$G214,'financial behaviour - Form Resp'!$H214,'financial behaviour - Form Resp'!$I214,'financial behaviour - Form Resp'!$J214),"Travel", IF('financial behaviour - Form Resp'!$J214=MAX('financial behaviour - Form Resp'!$G214,'financial behaviour - Form Resp'!$H214,'financial behaviour - Form Resp'!$I214,'financial behaviour - Form Resp'!$J214),"others","")))) -> Travel | L214: 2 | M214: Sometimes | N214: 31 | O214: 3 | P214: Yes | Q214: Weekly
B215: 19 | C215: Prefer not to say | D215: 17967.46 | E215: Hostel | F215: Weekly | G215: 0 | H215: 4318.9 | I215: 2175.42 | J215: 1069 | K215: =IF('financial behaviour - Form Resp'!$G215=MAX('financial behaviour - Form Resp'!$G215,'financial behaviour - Form Resp'!$H215,'financial behaviour - Form Resp'!$I215,'financial behaviour - Form Resp'!$J215),"Shopping", IF('financial behaviour - Form Resp'!$H215=MAX('financial behaviour - Form Resp'!$G215,'financial behaviour - Form Resp'!$H215,'financial behaviour - Form Resp'!$I215,'financial behaviour - Form Resp'!$J215),"Food", IF('financial behaviour - Form Resp'!$I215=MAX('financial behaviour - Form Resp'!$G215,'financial behaviour - Form Resp'!$H215,'financial behaviour - Form Resp'!$I215,'financial behaviour - Form Resp'!$J215),"Travel", IF('financial behaviour - Form Resp'!$J215=MAX('financial behaviour - Form Resp'!$G215,'financial behaviour - Form Resp'!$H215,'financial behaviour - Form Resp'!$I215,'financial behaviour - Form Resp'!$J215),"others","")))) -> Food | L215: 4 | M215: Sometimes | N215: 12 | O215: 2 | P215: Yes | Q215: Weekly
B216: 19 | C216: Male | D216: 26513.86 | E216: With Family | F216: Weekly | G216: 4365 | H216: 6791.62 | I216: 0 | J216: 3154 | K216: =IF('financial behaviour - Form Resp'!$G216=MAX('financial behaviour - Form Resp'!$G216,'financial behaviour - Form Resp'!$H216,'financial behaviour - Form Resp'!$I216,'financial behaviour - Form Resp'!$J216),"Shopping", IF('financial behaviour - Form Resp'!$H216=MAX('financial behaviour - Form Resp'!$G216,'financial behaviour - Form Resp'!$H216,'financial behaviour - Form Resp'!$I216,'financial behaviour - Form Resp'!$J216),"Food", IF('financial behaviour - Form Resp'!$I216=MAX('financial behaviour - Form Resp'!$G216,'financial behaviour - Form Resp'!$H216,'financial behaviour - Form Resp'!$I216,'financial behaviour - Form Resp'!$J216),"Travel", IF('financial behaviour - Form Resp'!$J216=MAX('financial behaviour - Form Resp'!$G216,'financial behaviour - Form Resp'!$H216,'financial behaviour - Form Resp'!$I216,'financial behaviour - Form Resp'!$J216),"others","")))) -> Food | L216: 2 | M216: Sometimes | N216: 0 | O216: 1 | P216: Yes | Q216: Never
B217: 18 | C217: Prefer not to say | D217: 12236.46 | E217: Hostel | F217: Monthly | G217: 12.8 | H217: 5678.22 | I217: 1027.68 | J217: 1625 | K217: =IF('financial behaviour - Form Resp'!$G217=MAX('financial behaviour - Form Resp'!$G217,'financial behaviour - Form Resp'!$H217,'financial behaviour - Form Resp'!$I217,'financial behaviour - Form Resp'!$J217),"Shopping", IF('financial behaviour - Form Resp'!$H217=MAX('financial behaviour - Form Resp'!$G217,'financial behaviour - Form Resp'!$H217,'financial behaviour - Form Resp'!$I217,'financial behaviour - Form Resp'!$J217),"Food", IF('financial behaviour - Form Resp'!$I217=MAX('financial behaviour - Form Resp'!$G217,'financial behaviour - Form Resp'!$H217,'financial behaviour - Form Resp'!$I217,'financial behaviour - Form Resp'!$J217),"Travel", IF('financial behaviour - Form Resp'!$J217=MAX('financial behaviour - Form Resp'!$G217,'financial behaviour - Form Resp'!$H217,'financial behaviour - Form Resp'!$I217,'financial behaviour - Form Resp'!$J217),"others","")))) -> Food | L217: 5 | M217: Yes | N217: 27 | O217: 2 | P217: Yes | Q217: Never
B218: 24 | C218: Prefer not to say | D218: 28223.81 | E218: PG | F218: Daily | G218: 72.36 | H218: 133.94 | I218: 8450.6 | J218: 2524 | K218: =IF('financial behaviour - Form Resp'!$G218=MAX('financial behaviour - Form Resp'!$G218,'financial behaviour - Form Resp'!$H218,'financial behaviour - Form Resp'!$I218,'financial behaviour - Form Resp'!$J218),"Shopping", IF('financial behaviour - Form Resp'!$H218=MAX('financial behaviour - Form Resp'!$G218,'financial behaviour - Form Resp'!$H218,'financial behaviour - Form Resp'!$I218,'financial behaviour - Form Resp'!$J218),"Food", IF('financial behaviour - Form Resp'!$I218=MAX('financial behaviour - Form Resp'!$G218,'financial behaviour - Form Resp'!$H218,'financial behaviour - Form Resp'!$I218,'financial behaviour - Form Resp'!$J218),"Travel", IF('financial behaviour - Form Resp'!$J218=MAX('financial behaviour - Form Resp'!$G218,'financial behaviour - Form Resp'!$H218,'financial behaviour - Form Resp'!$I218,'financial behaviour - Form Resp'!$J218),"others","")))) -> Travel | L218: 1 | M218: Yes | N218: 30 | O218: 1 | P218: No | Q218: Daily
... B5200: 21 | C5200: Male | D5200: 139.88 | E5200: PG | F5200: Weekly | G5200: 2341 | H5200: 2570 | I5200: 0 | J5200: 0 | K5200: =IF('financial behaviour - Form Resp'!$G5200=MAX('financial behaviour - Form Resp'!$G5200,'financial behaviour - Form Resp'!$H5200,'financial behaviour - Form Resp'!$I5200,'financial behaviour - Form Resp'!$J5200),"Shopping", IF('financial behaviour - Form Resp'!$H5200=MAX('financial behaviour - Form Resp'!$G5200,'financial behaviour - Form Resp'!$H5200,'financial behaviour - Form Resp'!$I5200,'financial behaviour - Form Resp'!$J5200),"Food", IF('financial behaviour - Form Resp'!$I5200=MAX('financial behaviour - Form Resp'!$G5200,'financial behaviour - Form Resp'!$H5200,'financial behaviour - Form Resp'!$I5200,'financial behaviour - Form Resp'!$J5200),"Travel", IF('financial behaviour - Form Resp'!$J5200=MAX('financial behaviour - Form Resp'!$G5200,'financial behaviour - Form Resp'!$H5200,'financial behaviour - Form Resp'!$I5200,'financial behaviour - Form Resp'!$J5200),"others","")))) -> Food | L5200: 2 | M5200: Yes | N5200: 60 | O5200: 2 | P5200: Yes | Q5200: Daily
...

Sheet Sheet1
